Workbook

Sheet README
B2: Demand Forecasting & Supply Planning Model
B3: Sample project for: Intern - Materials | Eaton Global Supply Chain Center of Excellence, Pune
B5: 1. What this project is
B6: This is a simple Excel model that forecasts monthly product demand and plans purchase/stock decisions around it - the two core activities mentioned in the Materials Intern job description (demand & supply process, material management, performance reporting, KPIs for cost/cash/service/continuity of supply).
B7: It uses 5 sample electrical products (like the kind Eaton makes) with 24 months of made-up but realistic sample sales history. All numbers are illustrative - in a real internship you would replace them with actual ERP/SAP data.
B9: 2. Why this method (and not Machine Learning)
B10: Demand planning teams in most companies still rely on simple, explainable methods - moving averages, safety stock, reorder point, EOQ - because they are fast to build, easy to explain to a manager, and easy to audit. This project intentionally uses only these basic, well-known formulas (no statistics packages, no ML models) so it is realistic for a Materials Intern role and easy for you to explain confidently in an interview.
B12: 3. What each sheet does
B13: Demand_History - Raw monthly demand (units) for 5 sample products over Jan 2024 - Dec 2025. This is the 'input data', shown in blue.
B14: Forecast - Predicts next month's demand using two simple methods: a 3-Month Moving Average and a Weighted Moving Average (recent months count more). It also checks how accurate each method was in the past (Forecast Accuracy %, on the right side of the sheet).
B15: Supply_Planning - For each product, calculates Safety Stock (buffer stock), Reorder Point (stock level that triggers a new order) and EOQ - Economic Order Quantity (the ideal quantity to order at once to balance ordering cost vs holding cost).
B16: Purchase_Plan - A 3-month rolling plan (Jan-Mar 2026) showing opening stock, forecast demand, whether to place an order, and the resulting closing stock for each product.
... B34: "I built a simple Excel-based demand forecasting and supply planning tool. It takes monthly sales history, forecasts the next month using a weighted moving average, checks forecast accuracy, and then calculates safety stock, reorder point and EOQ so the model can flag which products need to be reordered. I also built a KPI dashboard with charts so results are easy to review at a glance - similar to the kind of performance reporting mentioned in this role."

Sheet Demand_History
A1: Month | B1: MCB-32A | C1: CN-40 | D1: RL-10 | E1: TB-25 | F1: SD-63
A2: 45292 | B2: 1200 | C2: 884 | D2: 1682 | E2: 638 | F2: 460
A3: 45323 | B3: 1283 | C3: 905 | D3: 1626 | E3: 671 | F3: 458
A4: 45352 | B4: 1346 | C4: 899 | D4: 1539 | E4: 686 | F4: 442
A5: 45383 | B5: 1374 | C5: 869 | D5: 1447 | E5: 679 | F5: 416
A6: 45413 | B6: 1362 | C6: 825 | D6: 1377 | E6: 654 | F6: 390
A7: 45444 | B7: 1315 | C7: 779 | D7: 1351 | E7: 617 | F7: 370
A8: 45474 | B8: 1248 | C8: 746 | D8: 1378 | E8: 580 | F8: 364
A9: 45505 | B9: 1181 | C9: 735 | D9: 1454 | E9: 553 | F9: 374
A10: 45536 | B10: 1134 | C10: 751 | D10: 1561 | E10: 544 | F10: 398
A11: 45566 | B11: 1122 | C11: 791 | D11: 1673 | E11: 557 | F11: 432
A12: 45597 | B12: 1150 | C12: 845 | D12: 1763 | E12: 588 | F12: 466
A13: 45627 | B13: 1213 | C13: 901 | D13: 1809 | E13: 631 | F13: 494
... A25: 45992 | B25: 1309 | C25: 961 | D25: 1929 | E25: 667 | F25: 542
A27: Note: sample demand data generated for this project - replace with real ERP export for actual use.

Sheet Forecast
A1: Month | B1: SKU | C1: Actual Demand | D1: 3-Month MA Forecast | E1: Weighted MA Forecast | F1: Forecast Error | G1: Abs % Error | I1: SKU | J1: Forecast Accuracy % | L1: Higher % = forecast was closer to actual demand, on average, across all history.
A2: 45292 | B2: MCB-32A | C2: =Demand_History!B2 -> 1200 | D2: n/a | E2: n/a | F2: n/a | G2: n/a | I2: MCB-32A | J2: =1-AVERAGEIFS($G$2:$G$121,$B$2:$B$121,I2) -> 0.94468965
A3: 45323 | B3: MCB-32A | C3: =Demand_History!B3 -> 1283 | D3: n/a | E3: n/a | F3: n/a | G3: n/a | I3: CN-40 | J3: =1-AVERAGEIFS($G$2:$G$121,$B$2:$B$121,I3) -> 0.93872237
A4: 45352 | B4: MCB-32A | C4: =Demand_History!B4 -> 1346 | D4: n/a | E4: n/a | F4: n/a | G4: n/a | I4: RL-10 | J4: =1-AVERAGEIFS($G$2:$G$121,$B$2:$B$121,I4) -> 0.93315791
A5: 45383 | B5: MCB-32A | C5: =Demand_History!B5 -> 1374 | D5: =AVERAGE(Demand_History!B2:B4) -> 1276.3333 | E5: =(Demand_History!B2*1+Demand_History!B3*2+Demand_History!B4*3)/6 -> 1300.6667 | F5: =C5-E5 -> 73.333333 | G5: =IFERROR(ABS(F5)/C5,"") -> 0.053372149 | I5: TB-25 | J5: =1-AVERAGEIFS($G$2:$G$121,$B$2:$B$121,I5) -> 0.93802566
A6: 45413 | B6: MCB-32A | C6: =Demand_History!B6 -> 1362 | D6: =AVERAGE(Demand_History!B3:B5) -> 1334.3333 | E6: =(Demand_History!B3*1+Demand_History!B4*2+Demand_History!B5*3)/6 -> 1349.5 | F6: =C6-E6 -> 12.5 | G6: =IFERROR(ABS(F6)/C6,"") -> 0.0091776799 | I6: SD-63 | J6: =1-AVERAGEIFS($G$2:$G$121,$B$2:$B$121,I6) -> 0.92611546
A7: 45444 | B7: MCB-32A | C7: =Demand_History!B7 -> 1315 | D7: =AVERAGE(Demand_History!B4:B6) -> 1360.6667 | E7: =(Demand_History!B4*1+Demand_History!B5*2+Demand_History!B6*3)/6 -> 1363.3333 | F7: =C7-E7 -> -48.333333 | G7: =IFERROR(ABS(F7)/C7,"") -> 0.036755387
A8: 45474 | B8: MCB-32A | C8: =Demand_History!B8 -> 1248 | D8: =AVERAGE(Demand_History!B5:B7) -> 1350.3333 | E8: =(Demand_History!B5*1+Demand_History!B6*2+Demand_History!B7*3)/6 -> 1340.5 | F8: =C8-E8 -> -92.5 | G8: =IFERROR(ABS(F8)/C8,"") -> 0.07411859
A9: 45505 | B9: MCB-32A | C9: =Demand_History!B9 -> 1181 | D9: =AVERAGE(Demand_History!B6:B8) -> 1308.3333 | E9: =(Demand_History!B6*1+Demand_History!B7*2+Demand_History!B8*3)/6 -> 1289.3333 | F9: =C9-E9 -> -108.33333 | G9: =IFERROR(ABS(F9)/C9,"") -> 0.091730172
A10: 45536 | B10: MCB-32A | C10: =Demand_History!B10 -> 1134 | D10: =AVERAGE(Demand_History!B7:B9) -> 1248 | E10: =(Demand_History!B7*1+Demand_History!B8*2+Demand_History!B9*3)/6 -> 1225.6667 | F10: =C10-E10 -> -91.666667 | G10: =IFERROR(ABS(F10)/C10,"") -> 0.080834803
A11: 45566 | B11: MCB-32A | C11: =Demand_History!B11 -> 1122 | D11: =AVERAGE(Demand_History!B8:B10) -> 1187.6667 | E11: =(Demand_History!B8*1+Demand_History!B9*2+Demand_History!B10*3)/6 -> 1168.6667 | F11: =C11-E11 -> -46.666667 | G11: =IFERROR(ABS(F11)/C11,"") -> 0.041592395
A12: 45597 | B12: MCB-32A | C12: =Demand_History!B12 -> 1150 | D12: =AVERAGE(Demand_History!B9:B11) -> 1145.6667 | E12: =(Demand_History!B9*1+Demand_History!B10*2+Demand_History!B11*3)/6 -> 1135.8333 | F12: =C12-E12 -> 14.166667 | G12: =IFERROR(ABS(F12)/C12,"") -> 0.012318841
A13: 45627 | B13: MCB-32A | C13: =Demand_History!B13 -> 1213 | D13: =AVERAGE(Demand_History!B10:B12) -> 1135.3333 | E13: =(Demand_History!B10*1+Demand_History!B11*2+Demand_History!B12*3)/6 -> 1138 | F13: =C13-E13 -> 75 | G13: =IFERROR(ABS(F13)/C13,"") -> 0.061830173
A14: 45658 | B14: MCB-32A | C14: =Demand_History!B14 -> 1296 | D14: =AVERAGE(Demand_History!B11:B13) -> 1161.6667 | E14: =(Demand_History!B11*1+Demand_History!B12*2+Demand_History!B13*3)/6 -> 1176.8333 | F14: =C14-E14 -> 119.16667 | G14: =IFERROR(ABS(F14)/C14,"") -> 0.091949588
A15: 45689 | B15: MCB-32A | C15: =Demand_History!B15 -> 1379 | D15: =AVERAGE(Demand_History!B12:B14) -> 1219.6667 | E15: =(Demand_History!B12*1+Demand_History!B13*2+Demand_History!B14*3)/6 -> 1244 | F15: =C15-E15 -> 135 | G15: =IFERROR(ABS(F15)/C15,"") -> 0.097897027
A16: 45717 | B16: MCB-32A | C16: =Demand_History!B16 -> 1442 | D16: =AVERAGE(Demand_History!B13:B15) -> 1296 | E16: =(Demand_History!B13*1+Demand_History!B14*2+Demand_History!B15*3)/6 -> 1323.6667 | F16: =C16-E16 -> 118.33333 | G16: =IFERROR(ABS(F16)/C16,"") -> 0.082061951
A17: 45748 | B17: MCB-32A | C17: =Demand_History!B17 -> 1470 | D17: =AVERAGE(Demand_History!B14:B16) -> 1372.3333 | E17: =(Demand_History!B14*1+Demand_History!B15*2+Demand_History!B16*3)/6 -> 1396.6667 | F17: =C17-E17 -> 73.333333 | G17: =IFERROR(ABS(F17)/C17,"") -> 0.049886621
A18: 45778 | B18: MCB-32A | C18: =Demand_History!B18 -> 1458 | D18: =AVERAGE(Demand_History!B15:B17) -> 1430.3333 | E18: =(Demand_History!B15*1+Demand_History!B16*2+Demand_History!B17*3)/6 -> 1445.5 | F18: =C18-E18 -> 12.5 | G18: =IFERROR(ABS(F18)/C18,"") -> 0.0085733882
... A25: 45992 | B25: MCB-32A | C25: =Demand_History!B25 -> 1309 | D25: =AVERAGE(Demand_History!B22:B24) -> 1231.3333 | E25: =(Demand_History!B22*1+Demand_History!B23*2+Demand_History!B24*3)/6 -> 1234 | F25: =C25-E25 -> 75 | G25: =IFERROR(ABS(F25)/C25,"") -> 0.057295646
A26: 45292 | B26: CN-40 | C26: =Demand_History!C2 -> 884 | D26: n/a | E26: n/a | F26: n/a | G26: n/a
A27: 45323 | B27: CN-40 | C27: =Demand_History!C3 -> 905 | D27: n/a | E27: n/a | F27: n/a | G27: n/a
A28: 45352 | B28: CN-40 | C28: =Demand_History!C4 -> 899 | D28: n/a | E28: n/a | F28: n/a | G28: n/a
A29: 45383 | B29: CN-40 | C29: =Demand_History!C5 -> 869 | D29: =AVERAGE(Demand_History!C2:C4) -> 896 | E29: =(Demand_History!C2*1+Demand_History!C3*2+Demand_History!C4*3)/6 -> 898.5 | F29: =C29-E29 -> -29.5 | G29: =IFERROR(ABS(F29)/C29,"") -> 0.033947066
A30: 45413 | B30: CN-40 | C30: =Demand_History!C6 -> 825 | D30: =AVERAGE(Demand_History!C3:C5) -> 891 | E30: =(Demand_History!C3*1+Demand_History!C4*2+Demand_History!C5*3)/6 -> 885 | F30: =C30-E30 -> -60 | G30: =IFERROR(ABS(F30)/C30,"") -> 0.072727273
A31: 45444 | B31: CN-40 | C31: =Demand_History!C7 -> 779 | D31: =AVERAGE(Demand_History!C4:C6) -> 864.33333 | E31: =(Demand_History!C4*1+Demand_History!C5*2+Demand_History!C6*3)/6 -> 852 | F31: =C31-E31 -> -73 | G31: =IFERROR(ABS(F31)/C31,"") -> 0.093709884
A32: 45474 | B32: CN-40 | C32: =Demand_History!C8 -> 746 | D32: =AVERAGE(Demand_History!C5:C7) -> 824.33333 | E32: =(Demand_History!C5*1+Demand_History!C6*2+Demand_History!C7*3)/6 -> 809.33333 | F32: =C32-E32 -> -63.333333 | G32: =IFERROR(ABS(F32)/C32,"") -> 0.08489723
A33: 45505 | B33: CN-40 | C33: =Demand_History!C9 -> 735 | D33: =AVERAGE(Demand_History!C6:C8) -> 783.33333 | E33: =(Demand_History!C6*1+Demand_History!C7*2+Demand_History!C8*3)/6 -> 770.16667 | F33: =C33-E33 -> -35.166667 | G33: =IFERROR(ABS(F33)/C33,"") -> 0.047845805
A34: 45536 | B34: CN-40 | C34: =Demand_History!C10 -> 751 | D34: =AVERAGE(Demand_History!C7:C9) -> 753.33333 | E34: =(Demand_History!C7*1+Demand_History!C8*2+Demand_History!C9*3)/6 -> 746 | F34: =C34-E34 -> 5 | G34: =IFERROR(ABS(F34)/C34,"") -> 0.0066577896
A35: 45566 | B35: CN-40 | C35: =Demand_History!C11 -> 791 | D35: =AVERAGE(Demand_History!C8:C10) -> 744 | E35: =(Demand_History!C8*1+Demand_History!C9*2+Demand_History!C10*3)/6 -> 744.83333 | F35: =C35-E35 -> 46.166667 | G35: =IFERROR(ABS(F35)/C35,"") -> 0.058364939
A36: 45597 | B36: CN-40 | C36: =Demand_History!C12 -> 845 | D36: =AVERAGE(Demand_History!C9:C11) -> 759 | E36: =(Demand_History!C9*1+Demand_History!C10*2+Demand_History!C11*3)/6 -> 768.33333 | F36: =C36-E36 -> 76.666667 | G36: =IFERROR(ABS(F36)/C36,"") -> 0.090729783
A37: 45627 | B37: CN-40 | C37: =Demand_History!C13 -> 901 | D37: =AVERAGE(Demand_History!C10:C12) -> 795.66667 | E37: =(Demand_History!C10*1+Demand_History!C11*2+Demand_History!C12*3)/6 -> 811.33333 | F37: =C37-E37 -> 89.666667 | G37: =IFERROR(ABS(F37)/C37,"") -> 0.099519053
A38: 45658 | B38: CN-40 | C38: =Demand_History!C14 -> 944 | D38: =AVERAGE(Demand_History!C11:C13) -> 845.66667 | E38: =(Demand_History!C11*1+Demand_History!C12*2+Demand_History!C13*3)/6 -> 864 | F38: =C38-E38 -> 80 | G38: =IFERROR(ABS(F38)/C38,"") -> 0.084745763
A39: 45689 | B39: CN-40 | C39: =Demand_History!C15 -> 965 | D39: =AVERAGE(Demand_History!C12:C14) -> 896.66667 | E39: =(Demand_History!C12*1+Demand_History!C13*2+Demand_History!C14*3)/6 -> 913.16667 | F39: =C39-E39 -> 51.833333 | G39: =IFERROR(ABS(F39)/C39,"") -> 0.053713299
A40: 45717 | B40: CN-40 | C40: =Demand_History!C16 -> 959 | D40: =AVERAGE(Demand_History!C13:C15) -> 936.66667 | E40: =(Demand_History!C13*1+Demand_History!C14*2+Demand_History!C15*3)/6 -> 947.33333 | F40: =C40-E40 -> 11.666667 | G40: =IFERROR(ABS(F40)/C40,"") -> 0.01216545
... A49: 45992 | B49: CN-40 | C49: =Demand_History!C25 -> 961 | D49: =AVERAGE(Demand_History!C22:C24) -> 855.66667 | E49: =(Demand_History!C22*1+Demand_History!C23*2+Demand_History!C24*3)/6 -> 871.33333 | F49: =C49-E49 -> 89.666667 | G49: =IFERROR(ABS(F49)/C49,"") -> 0.093305584
A50: 45292 | B50: RL-10 | C50: =Demand_History!D2 -> 1682 | D50: n/a | E50: n/a | F50: n/a | G50: n/a
A51: 45323 | B51: RL-10 | C51: =Demand_History!D3 -> 1626 | D51: n/a | E51: n/a | F51: n/a | G51: n/a
A52: 45352 | B52: RL-10 | C52: =Demand_History!D4 -> 1539 | D52: n/a | E52: n/a | F52: n/a | G52: n/a
A53: 45383 | B53: RL-10 | C53: =Demand_History!D5 -> 1447 | D53: =AVERAGE(Demand_History!D2:D4) -> 1615.6667 | E53: =(Demand_History!D2*1+Demand_History!D3*2+Demand_History!D4*3)/6 -> 1591.8333 | F53: =C53-E53 -> -144.83333 | G53: =IFERROR(ABS(F53)/C53,"") -> 0.10009214
A54: 45413 | B54: RL-10 | C54: =Demand_History!D6 -> 1377 | D54: =AVERAGE(Demand_History!D3:D5) -> 1537.3333 | E54: =(Demand_History!D3*1+Demand_History!D4*2+Demand_History!D5*3)/6 -> 1507.5 | F54: =C54-E54 -> -130.5 | G54: =IFERROR(ABS(F54)/C54,"") -> 0.094771242
...

Sheet Supply_Planning
A1: Legend: | B1: Blue text = you can change this input | D1: Black text = calculated automatically
A3: SKU | B3: Avg Monthly Demand | C3: Max Monthly Demand | D3: Lead Time (months) | E3: Safety Stock | F3: Reorder Point | G3: Ordering Cost per Order (Rs) | H3: Holding Cost per Unit/Year (Rs) | I3: Annual Demand | J3: EOQ - Order Qty (units) | K3: Current Stock | L3: Stock Status
A4: MCB-32A | B4: =ROUND(AVERAGE(Demand_History!B2:B25),0) -> 1292 | C4: =MAX(Demand_History!B2:B25) -> 1470 | D4: 1 | E4: =ROUND((C4-B4)*D4,0) -> 178 | F4: =ROUND((B4*D4)+E4,0) -> 1470 | G4: 800 | H4: 40 | I4: =B4*12 -> 15504 | J4: =ROUND(SQRT((2*I4*G4)/H4),0) -> 788 | K4: 1650 | L4: =IF(K4<=F4,"Reorder Now","OK") -> OK
A5: CN-40 | B5: =ROUND(AVERAGE(Demand_History!C2:C25),0) -> 858 | C5: =MAX(Demand_History!C2:C25) -> 965 | D5: 1.5 | E5: =ROUND((C5-B5)*D5,0) -> 161 | F5: =ROUND((B5*D5)+E5,0) -> 1448 | G5: 600 | H5: 35 | I5: =B5*12 -> 10296 | J5: =ROUND(SQRT((2*I5*G5)/H5),0) -> 594 | K5: 1300 | L5: =IF(K5<=F5,"Reorder Now","OK") -> Reorder Now
A6: RL-10 | B6: =ROUND(AVERAGE(Demand_History!D2:D25),0) -> 1615 | C6: =MAX(Demand_History!D2:D25) -> 1929 | D6: 2 | E6: =ROUND((C6-B6)*D6,0) -> 628 | F6: =ROUND((B6*D6)+E6,0) -> 3858 | G6: 750 | H6: 25 | I6: =B6*12 -> 19380 | J6: =ROUND(SQRT((2*I6*G6)/H6),0) -> 1078 | K6: 4200 | L6: =IF(K6<=F6,"Reorder Now","OK") -> OK
A7: TB-25 | B7: =ROUND(AVERAGE(Demand_History!E2:E25),0) -> 635 | C7: =MAX(Demand_History!E2:E25) -> 722 | D7: 1 | E7: =ROUND((C7-B7)*D7,0) -> 87 | F7: =ROUND((B7*D7)+E7,0) -> 722 | G7: 500 | H7: 20 | I7: =B7*12 -> 7620 | J7: =ROUND(SQRT((2*I7*G7)/H7),0) -> 617 | K7: 650 | L7: =IF(K7<=F7,"Reorder Now","OK") -> Reorder Now
A8: SD-63 | B8: =ROUND(AVERAGE(Demand_History!F2:F25),0) -> 446 | C8: =MAX(Demand_History!F2:F25) -> 542 | D8: 2.5 | E8: =ROUND((C8-B8)*D8,0) -> 240 | F8: =ROUND((B8*D8)+E8,0) -> 1355 | G8: 900 | H8: 50 | I8: =B8*12 -> 5352 | J8: =ROUND(SQRT((2*I8*G8)/H8),0) -> 439 | K8: 1500 | L8: =IF(K8<=F8,"Reorder Now","OK") -> OK

Sheet Purchase_Plan
A1: Month | B1: SKU | C1: Opening Stock | D1: Forecast Demand | E1: Reorder Point | F1: Safety Stock | G1: Planned Order Qty | H1: Closing Stock
A2: 46023 | B2: MCB-32A | C2: =Supply_Planning!K4 -> 1650 | D2: =ROUND((Demand_History!B23*1+Demand_History!B24*2+Demand_History!B25*3)/6,0) -> 1273 | E2: =Supply_Planning!F4 -> 1470 | F2: =Supply_Planning!E4 -> 178 | G2: =IF((C2-D2)<E2,ROUND((E2+Supply_Planning!J4)-(C2-D2),0),0) -> 1881 | H2: =C2-D2+G2 -> 2258
A3: 46054 | B3: MCB-32A | C3: =H2 -> 2258 | D3: =ROUND((Demand_History!B23*1+Demand_History!B24*2+Demand_History!B25*3)/6,0) -> 1273 | E3: =Supply_Planning!F4 -> 1470 | F3: =Supply_Planning!E4 -> 178 | G3: =IF((C3-D3)<E3,ROUND((E3+Supply_Planning!J4)-(C3-D3),0),0) -> 1273 | H3: =C3-D3+G3 -> 2258
A4: 46082 | B4: MCB-32A | C4: =H3 -> 2258 | D4: =ROUND((Demand_History!B23*1+Demand_History!B24*2+Demand_History!B25*3)/6,0) -> 1273 | E4: =Supply_Planning!F4 -> 1470 | F4: =Supply_Planning!E4 -> 178 | G4: =IF((C4-D4)<E4,ROUND((E4+Supply_Planning!J4)-(C4-D4),0),0) -> 1273 | H4: =C4-D4+G4 -> 2258
A5: 46023 | B5: CN-40 | C5: =Supply_Planning!K5 -> 1300 | D5: =ROUND((Demand_History!C23*1+Demand_History!C24*2+Demand_History!C25*3)/6,0) -> 924 | E5: =Supply_Planning!F5 -> 1448 | F5: =Supply_Planning!E5 -> 161 | G5: =IF((C5-D5)<E5,ROUND((E5+Supply_Planning!J5)-(C5-D5),0),0) -> 1666 | H5: =C5-D5+G5 -> 2042
A6: 46054 | B6: CN-40 | C6: =H5 -> 2042 | D6: =ROUND((Demand_History!C23*1+Demand_History!C24*2+Demand_History!C25*3)/6,0) -> 924 | E6: =Supply_Planning!F5 -> 1448 | F6: =Supply_Planning!E5 -> 161 | G6: =IF((C6-D6)<E6,ROUND((E6+Supply_Planning!J5)-(C6-D6),0),0) -> 924 | H6: =C6-D6+G6 -> 2042
A7: 46082 | B7: CN-40 | C7: =H6 -> 2042 | D7: =ROUND((Demand_History!C23*1+Demand_History!C24*2+Demand_History!C25*3)/6,0) -> 924 | E7: =Supply_Planning!F5 -> 1448 | F7: =Supply_Planning!E5 -> 161 | G7: =IF((C7-D7)<E7,ROUND((E7+Supply_Planning!J5)-(C7-D7),0),0) -> 924 | H7: =C7-D7+G7 -> 2042
A8: 46023 | B8: RL-10 | C8: =Supply_Planning!K6 -> 4200 | D8: =ROUND((Demand_History!D23*1+Demand_History!D24*2+Demand_History!D25*3)/6,0) -> 1891 | E8: =Supply_Planning!F6 -> 3858 | F8: =Supply_Planning!E6 -> 628 | G8: =IF((C8-D8)<E8,ROUND((E8+Supply_Planning!J6)-(C8-D8),0),0) -> 2627 | H8: =C8-D8+G8 -> 4936
A9: 46054 | B9: RL-10 | C9: =H8 -> 4936 | D9: =ROUND((Demand_History!D23*1+Demand_History!D24*2+Demand_History!D25*3)/6,0) -> 1891 | E9: =Supply_Planning!F6 -> 3858 | F9: =Supply_Planning!E6 -> 628 | G9: =IF((C9-D9)<E9,ROUND((E9+Supply_Planning!J6)-(C9-D9),0),0) -> 1891 | H9: =C9-D9+G9 -> 4936
A10: 46082 | B10: RL-10 | C10: =H9 -> 4936 | D10: =ROUND((Demand_History!D23*1+Demand_History!D24*2+Demand_History!D25*3)/6,0) -> 1891 | E10: =Supply_Planning!F6 -> 3858 | F10: =Supply_Planning!E6 -> 628 | G10: =IF((C10-D10)<E10,ROUND((E10+Supply_Planning!J6)-(C10-D10),0),0) -> 1891 | H10: =C10-D10+G10 -> 4936
A11: 46023 | B11: TB-25 | C11: =Supply_Planning!K7 -> 650 | D11: =ROUND((Demand_History!E23*1+Demand_History!E24*2+Demand_History!E25*3)/6,0) -> 640 | E11: =Supply_Planning!F7 -> 722 | F11: =Supply_Planning!E7 -> 87 | G11: =IF((C11-D11)<E11,ROUND((E11+Supply_Planning!J7)-(C11-D11),0),0) -> 1329 | H11: =C11-D11+G11 -> 1339
A12: 46054 | B12: TB-25 | C12: =H11 -> 1339 | D12: =ROUND((Demand_History!E23*1+Demand_History!E24*2+Demand_History!E25*3)/6,0) -> 640 | E12: =Supply_Planning!F7 -> 722 | F12: =Supply_Planning!E7 -> 87 | G12: =IF((C12-D12)<E12,ROUND((E12+Supply_Planning!J7)-(C12-D12),0),0) -> 640 | H12: =C12-D12+G12 -> 1339
A13: 46082 | B13: TB-25 | C13: =H12 -> 1339 | D13: =ROUND((Demand_History!E23*1+Demand_History!E24*2+Demand_History!E25*3)/6,0) -> 640 | E13: =Supply_Planning!F7 -> 722 | F13: =Supply_Planning!E7 -> 87 | G13: =IF((C13-D13)<E13,ROUND((E13+Supply_Planning!J7)-(C13-D13),0),0) -> 640 | H13: =C13-D13+G13 -> 1339
A14: 46023 | B14: SD-63 | C14: =Supply_Planning!K8 -> 1500 | D14: =ROUND((Demand_History!F23*1+Demand_History!F24*2+Demand_History!F25*3)/6,0) -> 522 | E14: =Supply_Planning!F8 -> 1355 | F14: =Supply_Planning!E8 -> 240 | G14: =IF((C14-D14)<E14,ROUND((E14+Supply_Planning!J8)-(C14-D14),0),0) -> 816 | H14: =C14-D14+G14 -> 1794
A15: 46054 | B15: SD-63 | C15: =H14 -> 1794 | D15: =ROUND((Demand_History!F23*1+Demand_History!F24*2+Demand_History!F25*3)/6,0) -> 522 | E15: =Supply_Planning!F8 -> 1355 | F15: =Supply_Planning!E8 -> 240 | G15: =IF((C15-D15)<E15,ROUND((E15+Supply_Planning!J8)-(C15-D15),0),0) -> 522 | H15: =C15-D15+G15 -> 1794
A16: 46082 | B16: SD-63 | C16: =H15 -> 1794 | D16: =ROUND((Demand_History!F23*1+Demand_History!F24*2+Demand_History!F25*3)/6,0) -> 522 | E16: =Supply_Planning!F8 -> 1355 | F16: =Supply_Planning!E8 -> 240 | G16: =IF((C16-D16)<E16,ROUND((E16+Supply_Planning!J8)-(C16-D16),0),0) -> 522 | H16: =C16-D16+G16 -> 1794
A18: Note: Forecast Demand for Jan-Mar 2026 assumes flat demand based on the last 3 known actual months (Oct-Dec 2025), since no newer actuals exist yet.

Sheet KPI_Dashboard
A1: Materials & Supply Planning - KPI Dashboard
A3: SKU | B3: Forecast Accuracy % | C3: Avg Monthly Demand | D3: Reorder Point | E3: Current Stock | F3: Stock Status | G3: Inventory Turnover (x/yr)
A4: MCB-32A | B4: =Forecast!J2 -> 0.94468965 | C4: =Supply_Planning!B4 -> 1292 | D4: =Supply_Planning!F4 -> 1470 | E4: =Supply_Planning!K4 -> 1650 | F4: =Supply_Planning!L4 -> OK | G4: =IFERROR(Supply_Planning!I4/Supply_Planning!K4,"n/a") -> 9.3963636
A5: CN-40 | B5: =Forecast!J3 -> 0.93872237 | C5: =Supply_Planning!B5 -> 858 | D5: =Supply_Planning!F5 -> 1448 | E5: =Supply_Planning!K5 -> 1300 | F5: =Supply_Planning!L5 -> Reorder Now | G5: =IFERROR(Supply_Planning!I5/Supply_Planning!K5,"n/a") -> 7.92
A6: RL-10 | B6: =Forecast!J4 -> 0.93315791 | C6: =Supply_Planning!B6 -> 1615 | D6: =Supply_Planning!F6 -> 3858 | E6: =Supply_Planning!K6 -> 4200 | F6: =Supply_Planning!L6 -> OK | G6: =IFERROR(Supply_Planning!I6/Supply_Planning!K6,"n/a") -> 4.6142857
A7: TB-25 | B7: =Forecast!J5 -> 0.93802566 | C7: =Supply_Planning!B7 -> 635 | D7: =Supply_Planning!F7 -> 722 | E7: =Supply_Planning!K7 -> 650 | F7: =Supply_Planning!L7 -> Reorder Now | G7: =IFERROR(Supply_Planning!I7/Supply_Planning!K7,"n/a") -> 11.723077
A8: SD-63 | B8: =Forecast!J6 -> 0.92611546 | C8: =Supply_Planning!B8 -> 446 | D8: =Supply_Planning!F8 -> 1355 | E8: =Supply_Planning!K8 -> 1500 | F8: =Supply_Planning!L8 -> OK | G8: =IFERROR(Supply_Planning!I8/Supply_Planning!K8,"n/a") -> 3.568
A10: Overall Avg Forecast Accuracy: | B10: =AVERAGE(B4:B8) -> 0.93614221
A11: Products Needing Reorder Now: | B11: =COUNTIF(F4:F8,"Reorder Now") -> 2
A12: Overall Avg Inventory Turnover: | B12: =AVERAGE(G4:G8) -> 7.4443453
A20: Quick SKU Lookup
A21: Type or select a SKU code: | B21: MCB-32A
A22: Forecast Accuracy % | B22: =INDEX(B4:B8,MATCH($B$21,$A$4:$A$8,0)) -> 0.94468965
A23: Avg Monthly Demand | B23: =INDEX(C4:C8,MATCH($B$21,$A$4:$A$8,0)) -> 1292
A24: Reorder Point | B24: =INDEX(D4:D8,MATCH($B$21,$A$4:$A$8,0)) -> 1470
A25: Current Stock | B25: =INDEX(E4:E8,MATCH($B$21,$A$4:$A$8,0)) -> 1650
A26: Stock Status | B26: =INDEX(F4:F8,MATCH($B$21,$A$4:$A$8,0)) -> OK
A27: Inventory Turnover (x/yr) | B27: =INDEX(G4:G8,MATCH($B$21,$A$4:$A$8,0)) -> 9.3963636
